<?xml version="1.0" encoding="UTF-8"?>
<!-- Generated by org.testng.reporters.JUnitXMLReporter -->
<testsuite ignored="0" hostname="ASUS" failures="3" tests="6" name="Default test" time="16.198" errors="0" timestamp="2024-09-15T19:51:58 IST">
  <testcase classname="io.cucumber.testng.AbstractTestNGCucumberTests" name="runScenario" time="12.057">
    <failure type="java.lang.AssertionError" message="expected [https://practicetestautomation.com/logged-in-successfully/] but found [https://practicetestautomation.com/practice-test-login/]">
      <![CDATA[java.lang.AssertionError: expected [https://practicetestautomation.com/logged-in-successfully/] but found [https://practicetestautomation.com/practice-test-login/]
at org.testng.Assert.fail(Assert.java:99)
at org.testng.Assert.failNotEquals(Assert.java:1037)
at org.testng.Assert.assertEqualsImpl(Assert.java:140)
at org.testng.Assert.assertEquals(Assert.java:122)
at org.testng.Assert.assertEquals(Assert.java:629)
at org.testng.Assert.assertEquals(Assert.java:639)
at parallel.StepDefinition.user_should_login_successfully(StepDefinition.java:35)
at ✽.User should login successfully(classpath:parallel/login1.feature:37)
]]>
    </failure>
  </testcase> <!-- runScenario -->
  <testcase classname="io.cucumber.testng.AbstractTestNGCucumberTests" name="runScenario" time="12.119">
    <failure type="java.lang.AssertionError" message="expected [https://practicetestautomation.com/logged-in-successfully/] but found [https://practicetestautomation.com/practice-test-login/]">
      <![CDATA[java.lang.AssertionError: expected [https://practicetestautomation.com/logged-in-successfully/] but found [https://practicetestautomation.com/practice-test-login/]
at org.testng.Assert.fail(Assert.java:99)
at org.testng.Assert.failNotEquals(Assert.java:1037)
at org.testng.Assert.assertEqualsImpl(Assert.java:140)
at org.testng.Assert.assertEquals(Assert.java:122)
at org.testng.Assert.assertEquals(Assert.java:629)
at org.testng.Assert.assertEquals(Assert.java:639)
at parallel.StepDefinition.user_should_login_successfully(StepDefinition.java:35)
at ✽.User should login successfully(classpath:parallel/login2.feature:37)
]]>
    </failure>
  </testcase> <!-- runScenario -->
  <testcase classname="io.cucumber.testng.AbstractTestNGCucumberTests" name="runScenario" time="12.131">
    <failure type="java.lang.AssertionError" message="expected [https://practicetestautomation.com/logged-in-successfully/] but found [https://practicetestautomation.com/practice-test-login/]">
      <![CDATA[java.lang.AssertionError: expected [https://practicetestautomation.com/logged-in-successfully/] but found [https://practicetestautomation.com/practice-test-login/]
at org.testng.Assert.fail(Assert.java:99)
at org.testng.Assert.failNotEquals(Assert.java:1037)
at org.testng.Assert.assertEqualsImpl(Assert.java:140)
at org.testng.Assert.assertEquals(Assert.java:122)
at org.testng.Assert.assertEquals(Assert.java:629)
at org.testng.Assert.assertEquals(Assert.java:639)
at parallel.StepDefinition.user_should_login_successfully(StepDefinition.java:35)
at ✽.User should login successfully(classpath:parallel/login1.feature:29)
]]>
    </failure>
  </testcase> <!-- runScenario -->
  <testcase classname="io.cucumber.testng.AbstractTestNGCucumberTests" name="runScenario" time="12.214"/>
  <testcase classname="io.cucumber.testng.AbstractTestNGCucumberTests" name="runScenario" time="12.211"/>
  <testcase classname="io.cucumber.testng.AbstractTestNGCucumberTests" name="runScenario" time="12.277"/>
</testsuite> <!-- Default test -->
