<?xml version="1.0" encoding="UTF-8"?>
<!-- Generated by org.testng.reporters.JUnitReportReporter -->
<testsuite hostname="ASUS" failures="3" tests="6" name="parallel.ParallelRun" time="73.009" errors="0" timestamp="2024-09-15T19:51:59 IST" skipped="0">
  <testcase classname="parallel.ParallelRun" name="runScenario" time="12.214"/>
  <system-out/>
  <testcase classname="parallel.ParallelRun" name="runScenario" time="12.277"/>
  <system-out/>
  <testcase classname="parallel.ParallelRun" name="runScenario" time="12.057">
    <failure message="expected [https://practicetestautomation.com/logged-in-successfully/] but found [https://practicetestautomation.com/practice-test-login/]" type="java.lang.AssertionError">
      <![CDATA[java.lang.AssertionError: expected [https://practicetestautomation.com/logged-in-successfully/] but found [https://practicetestautomation.com/practice-test-login/]
at org.testng.Assert.fail(Assert.java:99)
at org.testng.Assert.failNotEquals(Assert.java:1037)
at org.testng.Assert.assertEqualsImpl(Assert.java:140)
at org.testng.Assert.assertEquals(Assert.java:122)
at org.testng.Assert.assertEquals(Assert.java:629)
at org.testng.Assert.assertEquals(Assert.java:639)
at parallel.StepDefinition.user_should_login_successfully(StepDefinition.java:35)
at ✽.User should login successfully(classpath:parallel/login1.feature:37)
]]>
    </failure>
  </testcase> <!-- runScenario -->
  <system-out/>
  <testcase classname="parallel.ParallelRun" name="runScenario" time="12.119">
    <failure message="expected [https://practicetestautomation.com/logged-in-successfully/] but found [https://practicetestautomation.com/practice-test-login/]" type="java.lang.AssertionError">
      <![CDATA[java.lang.AssertionError: expected [https://practicetestautomation.com/logged-in-successfully/] but found [https://practicetestautomation.com/practice-test-login/]
at org.testng.Assert.fail(Assert.java:99)
at org.testng.Assert.failNotEquals(Assert.java:1037)
at org.testng.Assert.assertEqualsImpl(Assert.java:140)
at org.testng.Assert.assertEquals(Assert.java:122)
at org.testng.Assert.assertEquals(Assert.java:629)
at org.testng.Assert.assertEquals(Assert.java:639)
at parallel.StepDefinition.user_should_login_successfully(StepDefinition.java:35)
at ✽.User should login successfully(classpath:parallel/login2.feature:37)
]]>
    </failure>
  </testcase> <!-- runScenario -->
  <system-out/>
  <testcase classname="parallel.ParallelRun" name="runScenario" time="12.211"/>
  <system-out/>
  <testcase classname="parallel.ParallelRun" name="runScenario" time="12.131">
    <failure message="expected [https://practicetestautomation.com/logged-in-successfully/] but found [https://practicetestautomation.com/practice-test-login/]" type="java.lang.AssertionError">
      <![CDATA[java.lang.AssertionError: expected [https://practicetestautomation.com/logged-in-successfully/] but found [https://practicetestautomation.com/practice-test-login/]
at org.testng.Assert.fail(Assert.java:99)
at org.testng.Assert.failNotEquals(Assert.java:1037)
at org.testng.Assert.assertEqualsImpl(Assert.java:140)
at org.testng.Assert.assertEquals(Assert.java:122)
at org.testng.Assert.assertEquals(Assert.java:629)
at org.testng.Assert.assertEquals(Assert.java:639)
at parallel.StepDefinition.user_should_login_successfully(StepDefinition.java:35)
at ✽.User should login successfully(classpath:parallel/login1.feature:29)
]]>
    </failure>
  </testcase> <!-- runScenario -->
  <system-out/>
</testsuite> <!-- parallel.ParallelRun -->
