<?xml version="1.0" encoding="UTF-8"?>
<!-- Generated by org.testng.reporters.JUnitReportReporter -->
<testsuite hostname="ASUS" failures="3" tests="6" name="parallel.ParallelRun" time="96.143" errors="0" timestamp="2024-09-15T19:55:28 IST" skipped="0">
  <testcase classname="parallel.ParallelRun" name="runScenario" time="15.319">
    <failure message="expected [https://practicetestautomation.com/logged-in-successfully/] but found [https://practicetestautomation.com/practice-test-login/]" type="java.lang.AssertionError">
      <![CDATA[java.lang.AssertionError: expected [https://practicetestautomation.com/logged-in-successfully/] but found [https://practicetestautomation.com/practice-test-login/]
at org.testng.Assert.fail(Assert.java:111)
at org.testng.Assert.failNotEquals(Assert.java:1578)
at org.testng.Assert.assertEqualsImpl(Assert.java:150)
at org.testng.Assert.assertEquals(Assert.java:132)
at org.testng.Assert.assertEquals(Assert.java:656)
at org.testng.Assert.assertEquals(Assert.java:666)
at parallel.StepDefinition.user_should_login_successfully(StepDefinition.java:35)
at ✽.User should login successfully(classpath:parallel/login2.feature:37)
]]>
    </failure>
  </testcase> <!-- runScenario -->
  <testcase classname="parallel.ParallelRun" name="runScenario" time="16.755">
    <failure message="expected [https://practicetestautomation.com/logged-in-successfully/] but found [https://practicetestautomation.com/practice-test-login/]" type="java.lang.AssertionError">
      <![CDATA[java.lang.AssertionError: expected [https://practicetestautomation.com/logged-in-successfully/] but found [https://practicetestautomation.com/practice-test-login/]
at org.testng.Assert.fail(Assert.java:111)
at org.testng.Assert.failNotEquals(Assert.java:1578)
at org.testng.Assert.assertEqualsImpl(Assert.java:150)
at org.testng.Assert.assertEquals(Assert.java:132)
at org.testng.Assert.assertEquals(Assert.java:656)
at org.testng.Assert.assertEquals(Assert.java:666)
at parallel.StepDefinition.user_should_login_successfully(StepDefinition.java:35)
at ✽.User should login successfully(classpath:parallel/login1.feature:29)
]]>
    </failure>
  </testcase> <!-- runScenario -->
  <testcase classname="parallel.ParallelRun" name="runScenario" time="15.331">
    <failure message="expected [https://practicetestautomation.com/logged-in-successfully/] but found [https://practicetestautomation.com/practice-test-login/]" type="java.lang.AssertionError">
      <![CDATA[java.lang.AssertionError: expected [https://practicetestautomation.com/logged-in-successfully/] but found [https://practicetestautomation.com/practice-test-login/]
at org.testng.Assert.fail(Assert.java:111)
at org.testng.Assert.failNotEquals(Assert.java:1578)
at org.testng.Assert.assertEqualsImpl(Assert.java:150)
at org.testng.Assert.assertEquals(Assert.java:132)
at org.testng.Assert.assertEquals(Assert.java:656)
at org.testng.Assert.assertEquals(Assert.java:666)
at parallel.StepDefinition.user_should_login_successfully(StepDefinition.java:35)
at ✽.User should login successfully(classpath:parallel/login1.feature:37)
]]>
    </failure>
  </testcase> <!-- runScenario -->
  <testcase classname="parallel.ParallelRun" name="runScenario" time="15.613"/>
  <testcase classname="parallel.ParallelRun" name="runScenario" time="17.622"/>
  <testcase classname="parallel.ParallelRun" name="runScenario" time="15.503"/>
</testsuite> <!-- parallel.ParallelRun -->
